Workbook

Sheet Hárok1
A1: STOLÁRSTVO | E1: MENO:
E2: TELEFÓN:
A3: SUČANSKÝ | E3: ADRESA:
E4: E-MAIL:
A5: CENOVÁ PONUKA INTERIÉROVÉ DVERE | E5: MATERIÁL:
A6: ROZMER | B6: MODEL | C6: MATERIÁL | D6: SKLO | E6: CENA ZA KUS | F6: ZÁRUBEŇ | G6: POČET | H6: CENA BEZ DPH
E7: =IFERROR(VLOOKUP(B7, Calc!A:B, 2, FALSE), 0)+IF(A7<=69, 0,IF(A7<=79, 3,IF(A7<=89, 6, 9))) -> 0 | F7: =TRUE -> TRUE | H7: =IF(ISBLANK(B7),0, G7*E7+IF(F7, IF(B7="v1", 79, 93), 0)) -> 0
E8: =IFERROR(VLOOKUP(B8, Calc!A:B, 2, FALSE), 0)+IF(A8<=69, 0,IF(A8<=79, 3,IF(A8<=89, 6, 9))) -> 0 | F8: =TRUE -> TRUE | H8: =IF(ISBLANK(B8),0, G8*E8+IF(F8, IF(B8="v1", 79, 93), 0)) -> 0
E9: =IFERROR(VLOOKUP(B9, Calc!A:B, 2, FALSE), 0)+IF(A9<=69, 0,IF(A9<=79, 3,IF(A9<=89, 6, 9))) -> 0 | F9: =TRUE -> TRUE | H9: =IF(ISBLANK(B9),0, G9*E9+IF(F9, IF(B9="v1", 79, 93), 0)) -> 0
E10: =IFERROR(VLOOKUP(B10, Calc!A:B, 2, FALSE), 0)+IF(A10<=69, 0,IF(A10<=79, 3,IF(A10<=89, 6, 9))) -> 0 | F10: =TRUE -> TRUE | H10: =IF(ISBLANK(B10),0, G10*E10+IF(F10, IF(B10="v1", 79, 93), 0)) -> 0
E11: =IFERROR(VLOOKUP(B11, Calc!A:B, 2, FALSE), 0)+IF(A11<=69, 0,IF(A11<=79, 3,IF(A11<=89, 6, 9))) -> 0 | F11: =TRUE -> TRUE | H11: =IF(ISBLANK(B11),0, G11*E11+IF(F11, IF(B11="v1", 79, 93), 0)) -> 0
E12: =IFERROR(VLOOKUP(B12, Calc!A:B, 2, FALSE), 0)+IF(A12<=69, 0,IF(A12<=79, 3,IF(A12<=89, 6, 9))) -> 0 | F12: =TRUE -> TRUE | H12: =IF(ISBLANK(B12),0, G12*E12+IF(F12, IF(B12="v1", 79, 93), 0)) -> 0
E13: =IFERROR(VLOOKUP(B13, Calc!A:B, 2, FALSE), 0)+IF(A13<=69, 0,IF(A13<=79, 3,IF(A13<=89, 6, 9))) -> 0 | F13: =TRUE -> TRUE | H13: =IF(ISBLANK(B13),0, G13*E13+IF(F13, IF(B13="v1", 79, 93), 0)) -> 0
E14: =IFERROR(VLOOKUP(B14, Calc!A:B, 2, FALSE), 0)+IF(A14<=69, 0,IF(A14<=79, 3,IF(A14<=89, 6, 9))) -> 0 | F14: =TRUE -> TRUE | H14: =IF(ISBLANK(B14),0, G14*E14+IF(F14, IF(B14="v1", 79, 93), 0)) -> 0
E15: =IFERROR(VLOOKUP(B15, Calc!A:B, 2, FALSE), 0)+IF(A15<=69, 0,IF(A15<=79, 3,IF(A15<=89, 6, 9))) -> 0 | F15: =TRUE -> TRUE | H15: =IF(ISBLANK(B15),0, G15*E15+IF(F15, IF(B15="v1", 79, 93), 0)) -> 0
A17: KĽUČKY nájdete na kluckynadvere.sk | F17: CENA ZA KUS | G17: POČET | H17: CENA BEZ DPH
H18: =G18*F18 -> 0
A19: Rozeta - BB štandardný interiérový zámok | F19: 0 | H19: =G19*F19 -> 0
A20: Rozeta - WC zámok | F20: 11 | H20: =G20*F20 -> 0
A21: Rozeta - FAB zámok | F21: 0 | H21: =G21*F21 -> 0
H22: =G22*F22 -> 0
A23: Montáž kľučiek a roziet 5€ | F23: 5 | H23: =G23*F23 -> 0
A25: DOVOZ | F25: MESTO | G25: POČET | H25: CENA BEZ DPH
A26: Okresné mesto. Cena prepravy je 0,5 € za km. Preprava sa počíta od výroby v obci Čachtice. | H26: =G26 -> 0
A27: Ulica
A28: Číslo domu
A29: Obec
A30: PSČ
A32: MONTÁŽ | G32: POČET | H32: CENA BEZ DPH
A33: Akciová montáž dverí so zárubňou 25 € / kus. Akcia platí pri počte 6 a viac kusov. Minimálna suma na dvoch montážnikov je 150 €. | G33: 0 | H33: =IF(G33>0,MAX(G33*25,150),0) -> 0
A35: ŠPECIÁLNE DOPLNKY | F35: CENA ZA KUS | G35: POČET | H35: CENA BEZ DPH
A36: Farebné krytky na pánty | F36: 12 | H36: =F36*G36 -> 0
A37: Farebné magnetické zámky | F37: 15 | H37: =F37*G37 -> 0
A38: Mušle na posuvné dvere | F38: 15 | H38: =F38*G38 -> 0
A39: Farebné skryté kovanie | H39: =F39*G39 -> 0
A40: Náprstník na posuvné dvere | F40: 10 | H40: =F40*G40 -> 0
A41: Príplatok za striekanie | H41: =F41*G41 -> 0
A42: Príplatok za dyhu | H42: =F42*G42 -> 0
A43: Príplatok za sklo | H43: =F43*G43 -> 0
A44: Vetracie mriežky do dverí | F44: 40 | H44: =F44*G44 -> 0
...

Sheet Calc
A1: Code | B1: Price
A2: R1 | B2: 170
A3: R2 | B3: 170
A4: R3 | B4: 192
A5: R4 | B5: 175
A6: R5 | B6: 175
A7: R6 | B7: 192
A8: R7 | B8: 192
A9: R8 | B9: 198
A10: R9 | B10: 202
A11: R10 | B11: 202
A12: R11 | B12: 198
A13: R12 | B13: 216
... A57: P16 | B57: 129
